2017-05-22 10:31:50
Traceback (most recent call last):
  File "/Users/wbond/Library/Application Support/Sublime Text 3/Packages/SFTP/sftp/commands.py", line 1772, in complete
  File "./python3.3/codecs.py", line 691, in read
  File "./python3.3/codecs.py", line 494, in read
UnicodeDecodeError: 'utf-8' codec can't decode byte 0xb1 in position 976: invalid start byte

During handling of the above exception, another exception occurred:

Traceback (most recent call last):
  File "/Users/wbond/Library/Application Support/Sublime Text 3/Packages/SFTP/sftp/commands.py", line 1743, in <lambda>
  File "/Users/wbond/Library/Application Support/Sublime Text 3/Packages/SFTP/sftp/commands.py", line 1775, in complete
  File "./python3.3/codecs.py", line 691, in read
  File "./python3.3/codecs.py", line 494, in read
  File "./python3.3/encodings/cp1252.py", line 15, in decode
UnicodeDecodeError: 'charmap' codec can't decode byte 0x8f in position 1258: character maps to <undefined>
2017-05-22 10:32:02
Traceback (most recent call last):
  File "/Users/wbond/Library/Application Support/Sublime Text 3/Packages/SFTP/sftp/commands.py", line 1772, in complete
  File "./python3.3/codecs.py", line 691, in read
  File "./python3.3/codecs.py", line 494, in read
UnicodeDecodeError: 'utf-8' codec can't decode byte 0xb1 in position 976: invalid start byte

During handling of the above exception, another exception occurred:

Traceback (most recent call last):
  File "/Users/wbond/Library/Application Support/Sublime Text 3/Packages/SFTP/sftp/commands.py", line 1743, in <lambda>
  File "/Users/wbond/Library/Application Support/Sublime Text 3/Packages/SFTP/sftp/commands.py", line 1775, in complete
  File "./python3.3/codecs.py", line 691, in read
  File "./python3.3/codecs.py", line 494, in read
  File "./python3.3/encodings/cp1252.py", line 15, in decode
UnicodeDecodeError: 'charmap' codec can't decode byte 0x8f in position 1258: character maps to <undefined>
2017-09-12 15:24:03
Traceback (most recent call last):
  File "/Users/wbond/Library/Application Support/Sublime Text 3/Packages/SFTP/sftp/commands.py", line 1743, in <lambda>
  File "/Users/wbond/Library/Application Support/Sublime Text 3/Packages/SFTP/sftp/commands.py", line 1778, in complete
  File "./python3.3/codecs.py", line 896, in open
FileNotFoundError: [Errno 2] No such file or directory: '/var/folders/gq/pcxb9zss73q3n0z56z3lgcw00000gn/T/sublime-sftp-diff-1505222640/fuel/app/views/public/templates/_modal-concours_bkup.twig'
2017-09-12 15:24:10
Traceback (most recent call last):
  File "/Users/wbond/Library/Application Support/Sublime Text 3/Packages/SFTP/sftp/commands.py", line 1743, in <lambda>
  File "/Users/wbond/Library/Application Support/Sublime Text 3/Packages/SFTP/sftp/commands.py", line 1778, in complete
  File "./python3.3/codecs.py", line 896, in open
FileNotFoundError: [Errno 2] No such file or directory: '/var/folders/gq/pcxb9zss73q3n0z56z3lgcw00000gn/T/sublime-sftp-diff-1505222649/fuel/app/views/public/templates/_modal-concours_bkup.twig'
2017-10-18 13:44:50
Traceback (most recent call last):
  File "/Users/wbond/Library/Application Support/Sublime Text 3/Packages/SFTP/sftp/commands.py", line 1743, in <lambda>
  File "/Users/wbond/Library/Application Support/Sublime Text 3/Packages/SFTP/sftp/commands.py", line 1778, in complete
  File "./python3.3/codecs.py", line 896, in open
FileNotFoundError: [Errno 2] No such file or directory: '/var/folders/gq/pcxb9zss73q3n0z56z3lgcw00000gn/T/sublime-sftp-diff-1508327090/.htaccess'
2017-10-18 13:45:09
Traceback (most recent call last):
  File "/Users/wbond/Library/Application Support/Sublime Text 3/Packages/SFTP/sftp/commands.py", line 1743, in <lambda>
  File "/Users/wbond/Library/Application Support/Sublime Text 3/Packages/SFTP/sftp/commands.py", line 1778, in complete
  File "./python3.3/codecs.py", line 896, in open
FileNotFoundError: [Errno 2] No such file or directory: '/var/folders/gq/pcxb9zss73q3n0z56z3lgcw00000gn/T/sublime-sftp-diff-1508327109/.htaccess'
2017-10-30 15:08:46
Traceback (most recent call last):
  File "/Users/wbond/Library/Application Support/Sublime Text 3/Packages/SFTP/sftp/commands.py", line 1743, in <lambda>
  File "/Users/wbond/Library/Application Support/Sublime Text 3/Packages/SFTP/sftp/commands.py", line 1778, in complete
  File "./python3.3/codecs.py", line 896, in open
FileNotFoundError: [Errno 2] No such file or directory: '/var/folders/gq/pcxb9zss73q3n0z56z3lgcw00000gn/T/sublime-sftp-diff-1509372525/public/assets/themes/public/js/application__DEV.js'
2017-11-02 08:58:51
Traceback (most recent call last):
  File "/Users/wbond/Library/Application Support/Sublime Text 3/Packages/SFTP/sftp/commands.py", line 432, in make_connection
  File "/Users/wbond/Library/Application Support/Sublime Text 3/Packages/SFTP/sftp/sftp_transport.py", line 492, in ls
SFTP.sftp.errors.PermissionError: Permission denied

During handling of the above exception, another exception occurred:

Traceback (most recent call last):
  File "/Users/wbond/Library/Application Support/Sublime Text 3/Packages/SFTP/sftp/threads.py", line 16, in run_with_except_hook
  File "/Users/wbond/Library/Application Support/Sublime Text 3/Packages/SFTP/sftp/threads.py", line 119, in handler
  File "/Users/wbond/Library/Application Support/Sublime Text 3/Packages/SFTP/sftp/commands.py", line 303, in run
  File "/Users/wbond/Library/Application Support/Sublime Text 3/Packages/SFTP/sftp/commands.py", line 441, in make_connection
  File "/Users/wbond/Library/Application Support/Sublime Text 3/Packages/SFTP/sftp/sftp_transport.py", line 492, in ls
SFTP.sftp.errors.PermissionError: Permission denied
2017-11-02 08:59:21
Traceback (most recent call last):
  File "/Users/wbond/Library/Application Support/Sublime Text 3/Packages/SFTP/sftp/commands.py", line 432, in make_connection
  File "/Users/wbond/Library/Application Support/Sublime Text 3/Packages/SFTP/sftp/sftp_transport.py", line 492, in ls
SFTP.sftp.errors.PermissionError: Permission denied

During handling of the above exception, another exception occurred:

Traceback (most recent call last):
  File "/Users/wbond/Library/Application Support/Sublime Text 3/Packages/SFTP/sftp/threads.py", line 16, in run_with_except_hook
  File "/Users/wbond/Library/Application Support/Sublime Text 3/Packages/SFTP/sftp/threads.py", line 119, in handler
  File "/Users/wbond/Library/Application Support/Sublime Text 3/Packages/SFTP/sftp/commands.py", line 303, in run
  File "/Users/wbond/Library/Application Support/Sublime Text 3/Packages/SFTP/sftp/commands.py", line 441, in make_connection
  File "/Users/wbond/Library/Application Support/Sublime Text 3/Packages/SFTP/sftp/sftp_transport.py", line 492, in ls
SFTP.sftp.errors.PermissionError: Permission denied
2017-11-02 08:59:29
Traceback (most recent call last):
  File "/Users/wbond/Library/Application Support/Sublime Text 3/Packages/SFTP/sftp/commands.py", line 432, in make_connection
  File "/Users/wbond/Library/Application Support/Sublime Text 3/Packages/SFTP/sftp/sftp_transport.py", line 492, in ls
SFTP.sftp.errors.PermissionError: Permission denied

During handling of the above exception, another exception occurred:

Traceback (most recent call last):
  File "/Users/wbond/Library/Application Support/Sublime Text 3/Packages/SFTP/sftp/threads.py", line 16, in run_with_except_hook
  File "/Users/wbond/Library/Application Support/Sublime Text 3/Packages/SFTP/sftp/threads.py", line 119, in handler
  File "/Users/wbond/Library/Application Support/Sublime Text 3/Packages/SFTP/sftp/commands.py", line 303, in run
  File "/Users/wbond/Library/Application Support/Sublime Text 3/Packages/SFTP/sftp/commands.py", line 441, in make_connection
  File "/Users/wbond/Library/Application Support/Sublime Text 3/Packages/SFTP/sftp/sftp_transport.py", line 492, in ls
SFTP.sftp.errors.PermissionError: Permission denied
2017-11-02 09:00:42
Traceback (most recent call last):
  File "/Users/wbond/Library/Application Support/Sublime Text 3/Packages/SFTP/sftp/commands.py", line 431, in make_connection
  File "/Users/wbond/Library/Application Support/Sublime Text 3/Packages/SFTP/sftp/sftp_transport.py", line 366, in cd
SFTP.sftp.errors.NotFoundError: Folder not found

During handling of the above exception, another exception occurred:

Traceback (most recent call last):
  File "/Users/wbond/Library/Application Support/Sublime Text 3/Packages/SFTP/sftp/threads.py", line 16, in run_with_except_hook
  File "/Users/wbond/Library/Application Support/Sublime Text 3/Packages/SFTP/sftp/threads.py", line 119, in handler
  File "/Users/wbond/Library/Application Support/Sublime Text 3/Packages/SFTP/sftp/commands.py", line 303, in run
  File "/Users/wbond/Library/Application Support/Sublime Text 3/Packages/SFTP/sftp/commands.py", line 441, in make_connection
  File "/Users/wbond/Library/Application Support/Sublime Text 3/Packages/SFTP/sftp/sftp_transport.py", line 492, in ls
SFTP.sftp.errors.PermissionError: Permission denied
2017-11-02 09:01:23
Traceback (most recent call last):
  File "/Users/wbond/Library/Application Support/Sublime Text 3/Packages/SFTP/sftp/commands.py", line 431, in make_connection
  File "/Users/wbond/Library/Application Support/Sublime Text 3/Packages/SFTP/sftp/sftp_transport.py", line 366, in cd
SFTP.sftp.errors.NotFoundError: Folder not found

During handling of the above exception, another exception occurred:

Traceback (most recent call last):
  File "/Users/wbond/Library/Application Support/Sublime Text 3/Packages/SFTP/sftp/threads.py", line 16, in run_with_except_hook
  File "/Users/wbond/Library/Application Support/Sublime Text 3/Packages/SFTP/sftp/threads.py", line 119, in handler
  File "/Users/wbond/Library/Application Support/Sublime Text 3/Packages/SFTP/sftp/commands.py", line 303, in run
  File "/Users/wbond/Library/Application Support/Sublime Text 3/Packages/SFTP/sftp/commands.py", line 441, in make_connection
  File "/Users/wbond/Library/Application Support/Sublime Text 3/Packages/SFTP/sftp/sftp_transport.py", line 492, in ls
SFTP.sftp.errors.PermissionError: Permission denied
2017-11-02 09:01:31
Traceback (most recent call last):
  File "/Users/wbond/Library/Application Support/Sublime Text 3/Packages/SFTP/sftp/commands.py", line 431, in make_connection
  File "/Users/wbond/Library/Application Support/Sublime Text 3/Packages/SFTP/sftp/sftp_transport.py", line 366, in cd
SFTP.sftp.errors.NotFoundError: Folder not found

During handling of the above exception, another exception occurred:

Traceback (most recent call last):
  File "/Users/wbond/Library/Application Support/Sublime Text 3/Packages/SFTP/sftp/threads.py", line 16, in run_with_except_hook
  File "/Users/wbond/Library/Application Support/Sublime Text 3/Packages/SFTP/sftp/threads.py", line 119, in handler
  File "/Users/wbond/Library/Application Support/Sublime Text 3/Packages/SFTP/sftp/commands.py", line 303, in run
  File "/Users/wbond/Library/Application Support/Sublime Text 3/Packages/SFTP/sftp/commands.py", line 441, in make_connection
  File "/Users/wbond/Library/Application Support/Sublime Text 3/Packages/SFTP/sftp/sftp_transport.py", line 492, in ls
SFTP.sftp.errors.PermissionError: Permission denied
2017-11-02 09:01:43
Traceback (most recent call last):
  File "/Users/wbond/Library/Application Support/Sublime Text 3/Packages/SFTP/sftp/commands.py", line 432, in make_connection
  File "/Users/wbond/Library/Application Support/Sublime Text 3/Packages/SFTP/sftp/sftp_transport.py", line 492, in ls
SFTP.sftp.errors.PermissionError: Permission denied

During handling of the above exception, another exception occurred:

Traceback (most recent call last):
  File "/Users/wbond/Library/Application Support/Sublime Text 3/Packages/SFTP/sftp/threads.py", line 16, in run_with_except_hook
  File "/Users/wbond/Library/Application Support/Sublime Text 3/Packages/SFTP/sftp/threads.py", line 119, in handler
  File "/Users/wbond/Library/Application Support/Sublime Text 3/Packages/SFTP/sftp/commands.py", line 303, in run
  File "/Users/wbond/Library/Application Support/Sublime Text 3/Packages/SFTP/sftp/commands.py", line 441, in make_connection
  File "/Users/wbond/Library/Application Support/Sublime Text 3/Packages/SFTP/sftp/sftp_transport.py", line 492, in ls
SFTP.sftp.errors.PermissionError: Permission denied
2017-11-02 09:03:08
Traceback (most recent call last):
  File "/Users/wbond/Library/Application Support/Sublime Text 3/Packages/SFTP/sftp/commands.py", line 1743, in <lambda>
  File "/Users/wbond/Library/Application Support/Sublime Text 3/Packages/SFTP/sftp/commands.py", line 1778, in complete
  File "./python3.3/codecs.py", line 896, in open
FileNotFoundError: [Errno 2] No such file or directory: '/var/folders/gq/pcxb9zss73q3n0z56z3lgcw00000gn/T/sublime-sftp-diff-1509609788/public/assets/themes/public/js/application__DEV.js'
